package old_2024.Exceptions.constructors.finallyException;

import java.io.IOException;

public class FinallyException {

	public static void main(final String[] args) throws IOException {
		//		try {
		//			try {
		//				printOne();
		//				throw new MyExceptionTwo("inside try MyExceptionOne");
		//			} catch (final MyExceptionOne myExceptionOne) {
		//				System.out.println("Catching myExceptionOne");
		//				throw new MyExceptionOne("Throwing MyExceptionOne");
		//			} finally {
		//				System.out.println("Catching myExceptionOne");
		//				throw new MyExceptionOne("Finally myExceptionOne");
		//			}
		//		} catch (final MyExceptionOne myExceptionOne) {
		//			myExceptionOne.printStackTrace();
		//		} finally {
		//			System.out.println("Calling second finally");
		//		}
	}

	//	public static void printOne() throws MyExceptionOne {
	//		System.out.println("printOne");
	//		throw new MyExceptionOne("Throw MyExceptionOnw");
	//	}
	//
	//	private static void printTwo() {
	//		System.out.println("printOne");
	//		throw new MyExceptionTwo("Throw MyExceptionTwo");
	//	}
}

